Workbook

Sheet ROUTE_CONFIG
A1: ROUTE CONFIGURATION - Transport Physics
A2: Define transport modes and warehouse costs. Yellow cells are editable.
A4: TABLE 1: TRANSPORT MODES
A5: Mode | B5: Lead Time (Fortnights) | C5: Cost Per Unit ($)
A6: Train | B6: 0 | C6: 0
A7: Truck | B7: 0 | C7: 0
A8: Plane | B8: 0 | C8: 0
A11: TABLE 2: WAREHOUSE CONFIGURATION
A12: Zone | B12: Current Capacity | C12: Cost Per Module | D12: Capacity Per Module
A13: Center | B13: 4800 | C13: 0 | D13: 0
A14: West | B14: 2500 | C14: 0 | D14: 0
A15: North | B15: 2000 | C15: 0 | D15: 0
A16: East | B16: 0 | C16: 0 | D16: 0
A17: South | B17: 0 | C17: 0 | D17: 0

Sheet LOGISTICS_DATA
A1: Route Cost Database (Generated from Case Parameters)
A2: From | B2: To | C2: Mode | D2: Cost | E2: LeadTime

Sheet ROUTE_OPTIMIZER
A1: ROUTE OPTIMIZER & MATRIX
A3: Cheapest Transport Mode Matrix ($ Cost)
B4: Center | C4: West | D4: North | E4: East | F4: South
A5: Center | B5: - | C5: N/A ($999999) | D5: N/A ($999999) | E5: N/A ($999999) | F5: N/A ($999999)
A6: West | B6: N/A ($999999) | C6: - | D6: N/A ($999999) | E6: N/A ($999999) | F6: N/A ($999999)
A7: North | B7: N/A ($999999) | C7: N/A ($999999) | D7: - | E7: N/A ($999999) | F7: N/A ($999999)
A8: East | B8: N/A ($999999) | C8: N/A ($999999) | D8: N/A ($999999) | E8: - | F8: N/A ($999999)
A9: South | B9: N/A ($999999) | C9: N/A ($999999) | D9: N/A ($999999) | E9: N/A ($999999) | F9: -
A12: ROUTE CALCULATOR
A13: From: | B13: Center
A14: To: | B14: North
A16: Mode | B16: Cost | C16: Lead Time | D16: Savings vs Air
A17: Train | B17: =SUMIFS(LOGISTICS_DATA!D:D, LOGISTICS_DATA!A:A, $B$13, LOGISTICS_DATA!B:B, $B$14, LOGISTICS_DATA!C:C, "Train") | C17: =SUMIFS(LOGISTICS_DATA!E:E, LOGISTICS_DATA!A:A, $B$13, LOGISTICS_DATA!B:B, $B$14, LOGISTICS_DATA!C:C, "Train")
A18: Truck | B18: =SUMIFS(LOGISTICS_DATA!D:D, LOGISTICS_DATA!A:A, $B$13, LOGISTICS_DATA!B:B, $B$14, LOGISTICS_DATA!C:C, "Truck") | C18: =SUMIFS(LOGISTICS_DATA!E:E, LOGISTICS_DATA!A:A, $B$13, LOGISTICS_DATA!B:B, $B$14, LOGISTICS_DATA!C:C, "Truck")
A19: Airplane | B19: =SUMIFS(LOGISTICS_DATA!D:D, LOGISTICS_DATA!A:A, $B$13, LOGISTICS_DATA!B:B, $B$14, LOGISTICS_DATA!C:C, "Airplane") | C19: =SUMIFS(LOGISTICS_DATA!E:E, LOGISTICS_DATA!A:A, $B$13, LOGISTICS_DATA!B:B, $B$14, LOGISTICS_DATA!C:C, "Airplane")

Sheet INVENTORY_TETRIS
A1: INVENTORY TETRIS - Zone-by-Zone Balance
A2: Balance inventory. Watch: 🔴STOCKOUT (red), 🟡WARNING >90% (yellow), 🟣OVERFLOW (purple).
A4: ═══ CENTER ZONE (Capacity: 4,800) ═══ | I4: Last Period Rent: $38,400
A5: Opening Inventory | B5: 3410 | D5: Capacity | E5: 4800 | G5: Rent Modules? | H5: 0
A7: Fortnight | B7: Production | C7: Sales | D7: Outgoing | E7: Incoming | F7: Projected Inv | G7: Capacity | H7: Flag
A8: FN1 | B8: 0 | C8: 0 | D8: 0 | E8: 0 | F8: =$B$5+B8+E8-D8-C8 | G8: =$E$5 + ($H$5 * ROUTE_CONFIG!$D$13) | H8: =IF(F8<0,"🔴 STOCKOUT!",IF(F8>G8,"🟣 OVERFLOW!",IF(F8>G8*0.9,"🟡 WARNING: >90%","✓ OK")))
A9: FN2 | B9: 0 | C9: 0 | D9: 0 | E9: 0 | F9: =F8+B9+E9-D9-C9 | G9: =$E$5 + ($H$5 * ROUTE_CONFIG!$D$13) | H9: =IF(F9<0,"🔴 STOCKOUT!",IF(F9>G9,"🟣 OVERFLOW!",IF(F9>G9*0.9,"🟡 WARNING: >90%","✓ OK")))
A10: FN3 | B10: 0 | C10: 0 | D10: 0 | E10: 0 | F10: =F9+B10+E10-D10-C10 | G10: =$E$5 + ($H$5 * ROUTE_CONFIG!$D$13) | H10: =IF(F10<0,"🔴 STOCKOUT!",IF(F10>G10,"🟣 OVERFLOW!",IF(F10>G10*0.9,"🟡 WARNING: >90%","✓ OK")))
A11: FN4 | B11: 0 | C11: 0 | D11: 0 | E11: 0 | F11: =F10+B11+E11-D11-C11 | G11: =$E$5 + ($H$5 * ROUTE_CONFIG!$D$13) | H11: =IF(F11<0,"🔴 STOCKOUT!",IF(F11>G11,"🟣 OVERFLOW!",IF(F11>G11*0.9,"🟡 WARNING: >90%","✓ OK")))
A12: FN5 | B12: 0 | C12: 0 | D12: 0 | E12: 0 | F12: =F11+B12+E12-D12-C12 | G12: =$E$5 + ($H$5 * ROUTE_CONFIG!$D$13) | H12: =IF(F12<0,"🔴 STOCKOUT!",IF(F12>G12,"🟣 OVERFLOW!",IF(F12>G12*0.9,"🟡 WARNING: >90%","✓ OK")))
A13: FN6 | B13: 0 | C13: 0 | D13: 0 | E13: 0 | F13: =F12+B13+E13-D13-C13 | G13: =$E$5 + ($H$5 * ROUTE_CONFIG!$D$13) | H13: =IF(F13<0,"🔴 STOCKOUT!",IF(F13>G13,"🟣 OVERFLOW!",IF(F13>G13*0.9,"🟡 WARNING: >90%","✓ OK")))
A14: FN7 | B14: 0 | C14: 0 | D14: 0 | E14: 0 | F14: =F13+B14+E14-D14-C14 | G14: =$E$5 + ($H$5 * ROUTE_CONFIG!$D$13) | H14: =IF(F14<0,"🔴 STOCKOUT!",IF(F14>G14,"🟣 OVERFLOW!",IF(F14>G14*0.9,"🟡 WARNING: >90%","✓ OK")))
A15: FN8 | B15: 0 | C15: 0 | D15: 0 | E15: 0 | F15: =F14+B15+E15-D15-C15 | G15: =$E$5 + ($H$5 * ROUTE_CONFIG!$D$13) | H15: =IF(F15<0,"🔴 STOCKOUT!",IF(F15>G15,"🟣 OVERFLOW!",IF(F15>G15*0.9,"🟡 WARNING: >90%","✓ OK")))
A18: ═══ WEST ZONE (Capacity: 2,500) ═══ | I18: Last Period Rent: $20,000
A19: Opening Inventory | B19: 1886 | D19: Capacity | E19: 2500 | G19: Rent Modules? | H19: 0
A21: Fortnight | B21: Production | C21: Sales | D21: Outgoing | E21: Incoming | F21: Projected Inv | G21: Capacity | H21: Flag | J21: Total Supply | K21: Total Demand
A22: FN1 | B22: 0 | C22: 0 | D22: 0 | E22: 0 | F22: =$B$19+B22+E22-D22-C22 | G22: =$E$19 + ($H$19 * ROUTE_CONFIG!$D$14) | H22: =IF(F22<0,"🔴 STOCKOUT!",IF(F22>G22,"🟣 OVERFLOW!",IF(F22>G22*0.9,"🟡 WARNING: >90%","✓ OK"))) | J22: =B22+E22 | K22: =C22+D22
A23: FN2 | B23: 0 | C23: 0 | D23: 0 | E23: 0 | F23: =F22+B23+E23-D23-C23 | G23: =$E$19 + ($H$19 * ROUTE_CONFIG!$D$14) | H23: =IF(F23<0,"🔴 STOCKOUT!",IF(F23>G23,"🟣 OVERFLOW!",IF(F23>G23*0.9,"🟡 WARNING: >90%","✓ OK"))) | J23: =B23+E23 | K23: =C23+D23
A24: FN3 | B24: 0 | C24: 0 | D24: 0 | E24: 0 | F24: =F23+B24+E24-D24-C24 | G24: =$E$19 + ($H$19 * ROUTE_CONFIG!$D$14) | H24: =IF(F24<0,"🔴 STOCKOUT!",IF(F24>G24,"🟣 OVERFLOW!",IF(F24>G24*0.9,"🟡 WARNING: >90%","✓ OK"))) | J24: =B24+E24 | K24: =C24+D24
A25: FN4 | B25: 0 | C25: 0 | D25: 0 | E25: 0 | F25: =F24+B25+E25-D25-C25 | G25: =$E$19 + ($H$19 * ROUTE_CONFIG!$D$14) | H25: =IF(F25<0,"🔴 STOCKOUT!",IF(F25>G25,"🟣 OVERFLOW!",IF(F25>G25*0.9,"🟡 WARNING: >90%","✓ OK"))) | J25: =B25+E25 | K25: =C25+D25
A26: FN5 | B26: 0 | C26: 0 | D26: 0 | E26: 0 | F26: =F25+B26+E26-D26-C26 | G26: =$E$19 + ($H$19 * ROUTE_CONFIG!$D$14) | H26: =IF(F26<0,"🔴 STOCKOUT!",IF(F26>G26,"🟣 OVERFLOW!",IF(F26>G26*0.9,"🟡 WARNING: >90%","✓ OK"))) | J26: =B26+E26 | K26: =C26+D26
A27: FN6 | B27: 0 | C27: 0 | D27: 0 | E27: 0 | F27: =F26+B27+E27-D27-C27 | G27: =$E$19 + ($H$19 * ROUTE_CONFIG!$D$14) | H27: =IF(F27<0,"🔴 STOCKOUT!",IF(F27>G27,"🟣 OVERFLOW!",IF(F27>G27*0.9,"🟡 WARNING: >90%","✓ OK"))) | J27: =B27+E27 | K27: =C27+D27
A28: FN7 | B28: 0 | C28: 0 | D28: 0 | E28: 0 | F28: =F27+B28+E28-D28-C28 | G28: =$E$19 + ($H$19 * ROUTE_CONFIG!$D$14) | H28: =IF(F28<0,"🔴 STOCKOUT!",IF(F28>G28,"🟣 OVERFLOW!",IF(F28>G28*0.9,"🟡 WARNING: >90%","✓ OK"))) | J28: =B28+E28 | K28: =C28+D28
A29: FN8 | B29: 0 | C29: 0 | D29: 0 | E29: 0 | F29: =F28+B29+E29-D29-C29 | G29: =$E$19 + ($H$19 * ROUTE_CONFIG!$D$14) | H29: =IF(F29<0,"🔴 STOCKOUT!",IF(F29>G29,"🟣 OVERFLOW!",IF(F29>G29*0.9,"🟡 WARNING: >90%","✓ OK"))) | J29: =B29+E29 | K29: =C29+D29
A32: ═══ NORTH ZONE (Capacity: 2,000) ═══ | I32: Last Period Rent: $16,000
A33: Opening Inventory | B33: 1720 | D33: Capacity | E33: 2000 | G33: Rent Modules? | H33: 0
A35: Fortnight | B35: Production | C35: Sales | D35: Outgoing | E35: Incoming | F35: Projected Inv | G35: Capacity | H35: Flag | J35: Total Supply | K35: Total Demand
A36: FN1 | B36: 0 | C36: 0 | D36: 0 | E36: 0 | F36: =$B$33+B36+E36-D36-C36 | G36: =$E$33 + ($H$33 * ROUTE_CONFIG!$D$15) | H36: =IF(F36<0,"🔴 STOCKOUT!",IF(F36>G36,"🟣 OVERFLOW!",IF(F36>G36*0.9,"🟡 WARNING: >90%","✓ OK"))) | J36: =B36+E36 | K36: =C36+D36
A37: FN2 | B37: 0 | C37: 0 | D37: 0 | E37: 0 | F37: =F36+B37+E37-D37-C37 | G37: =$E$33 + ($H$33 * ROUTE_CONFIG!$D$15) | H37: =IF(F37<0,"🔴 STOCKOUT!",IF(F37>G37,"🟣 OVERFLOW!",IF(F37>G37*0.9,"🟡 WARNING: >90%","✓ OK"))) | J37: =B37+E37 | K37: =C37+D37
A38: FN3 | B38: 0 | C38: 0 | D38: 0 | E38: 0 | F38: =F37+B38+E38-D38-C38 | G38: =$E$33 + ($H$33 * ROUTE_CONFIG!$D$15) | H38: =IF(F38<0,"🔴 STOCKOUT!",IF(F38>G38,"🟣 OVERFLOW!",IF(F38>G38*0.9,"🟡 WARNING: >90%","✓ OK"))) | J38: =B38+E38 | K38: =C38+D38
A39: FN4 | B39: 0 | C39: 0 | D39: 0 | E39: 0 | F39: =F38+B39+E39-D39-C39 | G39: =$E$33 + ($H$33 * ROUTE_CONFIG!$D$15) | H39: =IF(F39<0,"🔴 STOCKOUT!",IF(F39>G39,"🟣 OVERFLOW!",IF(F39>G39*0.9,"🟡 WARNING: >90%","✓ OK"))) | J39: =B39+E39 | K39: =C39+D39
A40: FN5 | B40: 0 | C40: 0 | D40: 0 | E40: 0 | F40: =F39+B40+E40-D40-C40 | G40: =$E$33 + ($H$33 * ROUTE_CONFIG!$D$15) | H40: =IF(F40<0,"🔴 STOCKOUT!",IF(F40>G40,"🟣 OVERFLOW!",IF(F40>G40*0.9,"🟡 WARNING: >90%","✓ OK"))) | J40: =B40+E40 | K40: =C40+D40
A41: FN6 | B41: 0 | C41: 0 | D41: 0 | E41: 0 | F41: =F40+B41+E41-D41-C41 | G41: =$E$33 + ($H$33 * ROUTE_CONFIG!$D$15) | H41: =IF(F41<0,"🔴 STOCKOUT!",IF(F41>G41,"🟣 OVERFLOW!",IF(F41>G41*0.9,"🟡 WARNING: >90%","✓ OK"))) | J41: =B41+E41 | K41: =C41+D41
A42: FN7 | B42: 0 | C42: 0 | D42: 0 | E42: 0 | F42: =F41+B42+E42-D42-C42 | G42: =$E$33 + ($H$33 * ROUTE_CONFIG!$D$15) | H42: =IF(F42<0,"🔴 STOCKOUT!",IF(F42>G42,"🟣 OVERFLOW!",IF(F42>G42*0.9,"🟡 WARNING: >90%","✓ OK"))) | J42: =B42+E42 | K42: =C42+D42
A43: FN8 | B43: 0 | C43: 0 | D43: 0 | E43: 0 | F43: =F42+B43+E43-D43-C43 | G43: =$E$33 + ($H$33 * ROUTE_CONFIG!$D$15) | H43: =IF(F43<0,"🔴 STOCKOUT!",IF(F43>G43,"🟣 OVERFLOW!",IF(F43>G43*0.9,"🟡 WARNING: >90%","✓ OK"))) | J43: =B43+E43 | K43: =C43+D43
A46: ═══ EAST ZONE (Capacity: 0) ═══
A47: Opening Inventory | B47: 0 | D47: Capacity | E47: 0 | G47: Rent Modules? | H47: 0
A49: Fortnight | B49: Production | C49: Sales | D49: Outgoing | E49: Incoming | F49: Projected Inv | G49: Capacity | H49: Flag | J49: Total Supply | K49: Total Demand
A50: FN1 | B50: 0 | C50: 0 | D50: 0 | E50: 0 | F50: =$B$47+B50+E50-D50-C50 | G50: =$E$47 + ($H$47 * ROUTE_CONFIG!$D$16) | H50: =IF(F50<0,"🔴 STOCKOUT!",IF(F50>G50,"🟣 OVERFLOW!",IF(F50>G50*0.9,"🟡 WARNING: >90%","✓ OK"))) | J50: =B50+E50 | K50: =C50+D50
A51: FN2 | B51: 0 | C51: 0 | D51: 0 | E51: 0 | F51: =F50+B51+E51-D51-C51 | G51: =$E$47 + ($H$47 * ROUTE_CONFIG!$D$16) | H51: =IF(F51<0,"🔴 STOCKOUT!",IF(F51>G51,"🟣 OVERFLOW!",IF(F51>G51*0.9,"🟡 WARNING: >90%","✓ OK"))) | J51: =B51+E51 | K51: =C51+D51
...

Sheet SHIPMENT_BUILDER
A1: SHIPMENT BUILDER - Plan Your Transfers
A2: Add shipments here. MANUALLY update Outgoing/Incoming in INVENTORY_TETRIS (shifted by Lead Time).
A4: SHIPMENT LOG | M4: HISTORICAL COST BENCHMARKS
A5: Values | B5: From Zone | C5: To Zone | D5: Transport Mode | E5: Units | F5: Cost/Unit | G5: Total Cost | H5: Ship FN | I5: Lead Time | J5: Arrive FN | M5: Route | N5: Benchmark $/Unit
A6: Shipment 1 | F6: =IF(ISBLANK(D6), 0, VLOOKUP(D6, ROUTE_CONFIG!$A$6:$C$8, 3, FALSE)) | G6: =IF(ISBLANK(D6), 0, E6*F6) | I6: =IF(ISBLANK(D6), 0, VLOOKUP(D6, ROUTE_CONFIG!$A$6:$C$8, 2, FALSE)) | J6: =IF(ISBLANK(D6), 0, H6+I6) | M6: Train (Center - West) | N6: 13.2
A7: Shipment 2 | F7: =IF(ISBLANK(D7), 0, VLOOKUP(D7, ROUTE_CONFIG!$A$6:$C$8, 3, FALSE)) | G7: =IF(ISBLANK(D7), 0, E7*F7) | I7: =IF(ISBLANK(D7), 0, VLOOKUP(D7, ROUTE_CONFIG!$A$6:$C$8, 2, FALSE)) | J7: =IF(ISBLANK(D7), 0, H7+I7) | M7: Train (Center - North) | N7: 16.319925
A8: Shipment 3 | F8: =IF(ISBLANK(D8), 0, VLOOKUP(D8, ROUTE_CONFIG!$A$6:$C$8, 3, FALSE)) | G8: =IF(ISBLANK(D8), 0, E8*F8) | I8: =IF(ISBLANK(D8), 0, VLOOKUP(D8, ROUTE_CONFIG!$A$6:$C$8, 2, FALSE)) | J8: =IF(ISBLANK(D8), 0, H8+I8)
A9: Shipment 4 | F9: =IF(ISBLANK(D9), 0, VLOOKUP(D9, ROUTE_CONFIG!$A$6:$C$8, 3, FALSE)) | G9: =IF(ISBLANK(D9), 0, E9*F9) | I9: =IF(ISBLANK(D9), 0, VLOOKUP(D9, ROUTE_CONFIG!$A$6:$C$8, 2, FALSE)) | J9: =IF(ISBLANK(D9), 0, H9+I9)
A10: Shipment 5 | F10: =IF(ISBLANK(D10), 0, VLOOKUP(D10, ROUTE_CONFIG!$A$6:$C$8, 3, FALSE)) | G10: =IF(ISBLANK(D10), 0, E10*F10) | I10: =IF(ISBLANK(D10), 0, VLOOKUP(D10, ROUTE_CONFIG!$A$6:$C$8, 2, FALSE)) | J10: =IF(ISBLANK(D10), 0, H10+I10)
A11: Shipment 6 | F11: =IF(ISBLANK(D11), 0, VLOOKUP(D11, ROUTE_CONFIG!$A$6:$C$8, 3, FALSE)) | G11: =IF(ISBLANK(D11), 0, E11*F11) | I11: =IF(ISBLANK(D11), 0, VLOOKUP(D11, ROUTE_CONFIG!$A$6:$C$8, 2, FALSE)) | J11: =IF(ISBLANK(D11), 0, H11+I11)
A12: Shipment 7 | F12: =IF(ISBLANK(D12), 0, VLOOKUP(D12, ROUTE_CONFIG!$A$6:$C$8, 3, FALSE)) | G12: =IF(ISBLANK(D12), 0, E12*F12) | I12: =IF(ISBLANK(D12), 0, VLOOKUP(D12, ROUTE_CONFIG!$A$6:$C$8, 2, FALSE)) | J12: =IF(ISBLANK(D12), 0, H12+I12)
A13: Shipment 8 | F13: =IF(ISBLANK(D13), 0, VLOOKUP(D13, ROUTE_CONFIG!$A$6:$C$8, 3, FALSE)) | G13: =IF(ISBLANK(D13), 0, E13*F13) | I13: =IF(ISBLANK(D13), 0, VLOOKUP(D13, ROUTE_CONFIG!$A$6:$C$8, 2, FALSE)) | J13: =IF(ISBLANK(D13), 0, H13+I13)
A14: Shipment 9 | F14: =IF(ISBLANK(D14), 0, VLOOKUP(D14, ROUTE_CONFIG!$A$6:$C$8, 3, FALSE)) | G14: =IF(ISBLANK(D14), 0, E14*F14) | I14: =IF(ISBLANK(D14), 0, VLOOKUP(D14, ROUTE_CONFIG!$A$6:$C$8, 2, FALSE)) | J14: =IF(ISBLANK(D14), 0, H14+I14)
A15: Shipment 10 | F15: =IF(ISBLANK(D15), 0, VLOOKUP(D15, ROUTE_CONFIG!$A$6:$C$8, 3, FALSE)) | G15: =IF(ISBLANK(D15), 0, E15*F15) | I15: =IF(ISBLANK(D15), 0, VLOOKUP(D15, ROUTE_CONFIG!$A$6:$C$8, 2, FALSE)) | J15: =IF(ISBLANK(D15), 0, H15+I15)
A16: Shipment 11 | F16: =IF(ISBLANK(D16), 0, VLOOKUP(D16, ROUTE_CONFIG!$A$6:$C$8, 3, FALSE)) | G16: =IF(ISBLANK(D16), 0, E16*F16) | I16: =IF(ISBLANK(D16), 0, VLOOKUP(D16, ROUTE_CONFIG!$A$6:$C$8, 2, FALSE)) | J16: =IF(ISBLANK(D16), 0, H16+I16)
A17: Shipment 12 | F17: =IF(ISBLANK(D17), 0, VLOOKUP(D17, ROUTE_CONFIG!$A$6:$C$8, 3, FALSE)) | G17: =IF(ISBLANK(D17), 0, E17*F17) | I17: =IF(ISBLANK(D17), 0, VLOOKUP(D17, ROUTE_CONFIG!$A$6:$C$8, 2, FALSE)) | J17: =IF(ISBLANK(D17), 0, H17+I17)
A18: Shipment 13 | F18: =IF(ISBLANK(D18), 0, VLOOKUP(D18, ROUTE_CONFIG!$A$6:$C$8, 3, FALSE)) | G18: =IF(ISBLANK(D18), 0, E18*F18) | I18: =IF(ISBLANK(D18), 0, VLOOKUP(D18, ROUTE_CONFIG!$A$6:$C$8, 2, FALSE)) | J18: =IF(ISBLANK(D18), 0, H18+I18)
A19: Shipment 14 | F19: =IF(ISBLANK(D19), 0, VLOOKUP(D19, ROUTE_CONFIG!$A$6:$C$8, 3, FALSE)) | G19: =IF(ISBLANK(D19), 0, E19*F19) | I19: =IF(ISBLANK(D19), 0, VLOOKUP(D19, ROUTE_CONFIG!$A$6:$C$8, 2, FALSE)) | J19: =IF(ISBLANK(D19), 0, H19+I19)
... A25: Shipment 20 | F25: =IF(ISBLANK(D25), 0, VLOOKUP(D25, ROUTE_CONFIG!$A$6:$C$8, 3, FALSE)) | G25: =IF(ISBLANK(D25), 0, E25*F25) | I25: =IF(ISBLANK(D25), 0, VLOOKUP(D25, ROUTE_CONFIG!$A$6:$C$8, 2, FALSE)) | J25: =IF(ISBLANK(D25), 0, H25+I25)
A27: ⚠️ Red cells = Cost >20% above avg benchmark ($14.76 avg)

Sheet UPLOAD_READY_LOGISTICS
A1: LOGISTICS DECISIONS - ExSim Upload Format
A2: Copy these values to the web platform.
A4: Planned Shipments
A5: From | B5: To | C5: Material | D5: Amount | E5: F1 | F5: F2 | G5: F3 | H5: F4 | I5: F5 | J5: F6 | K5: F7 | L5: F8
A6: =SHIPMENT_BUILDER!B6 | B6: =SHIPMENT_BUILDER!C6 | C6: Electroclean | D6: =SHIPMENT_BUILDER!E6 | E6: =IF(SHIPMENT_BUILDER!$H$6=1, SHIPMENT_BUILDER!$E$6, 0) | F6: =IF(SHIPMENT_BUILDER!$H$6=2, SHIPMENT_BUILDER!$E$6, 0) | G6: =IF(SHIPMENT_BUILDER!$H$6=3, SHIPMENT_BUILDER!$E$6, 0) | H6: =IF(SHIPMENT_BUILDER!$H$6=4, SHIPMENT_BUILDER!$E$6, 0) | I6: =IF(SHIPMENT_BUILDER!$H$6=5, SHIPMENT_BUILDER!$E$6, 0) | J6: =IF(SHIPMENT_BUILDER!$H$6=6, SHIPMENT_BUILDER!$E$6, 0) | K6: =IF(SHIPMENT_BUILDER!$H$6=7, SHIPMENT_BUILDER!$E$6, 0) | L6: =IF(SHIPMENT_BUILDER!$H$6=8, SHIPMENT_BUILDER!$E$6, 0)
A7: =SHIPMENT_BUILDER!B7 | B7: =SHIPMENT_BUILDER!C7 | C7: Electroclean | D7: =SHIPMENT_BUILDER!E7 | E7: =IF(SHIPMENT_BUILDER!$H$7=1, SHIPMENT_BUILDER!$E$7, 0) | F7: =IF(SHIPMENT_BUILDER!$H$7=2, SHIPMENT_BUILDER!$E$7, 0) | G7: =IF(SHIPMENT_BUILDER!$H$7=3, SHIPMENT_BUILDER!$E$7, 0) | H7: =IF(SHIPMENT_BUILDER!$H$7=4, SHIPMENT_BUILDER!$E$7, 0) | I7: =IF(SHIPMENT_BUILDER!$H$7=5, SHIPMENT_BUILDER!$E$7, 0) | J7: =IF(SHIPMENT_BUILDER!$H$7=6, SHIPMENT_BUILDER!$E$7, 0) | K7: =IF(SHIPMENT_BUILDER!$H$7=7, SHIPMENT_BUILDER!$E$7, 0) | L7: =IF(SHIPMENT_BUILDER!$H$7=8, SHIPMENT_BUILDER!$E$7, 0)
A8: =SHIPMENT_BUILDER!B8 | B8: =SHIPMENT_BUILDER!C8 | C8: Electroclean | D8: =SHIPMENT_BUILDER!E8 | E8: =IF(SHIPMENT_BUILDER!$H$8=1, SHIPMENT_BUILDER!$E$8, 0) | F8: =IF(SHIPMENT_BUILDER!$H$8=2, SHIPMENT_BUILDER!$E$8, 0) | G8: =IF(SHIPMENT_BUILDER!$H$8=3, SHIPMENT_BUILDER!$E$8, 0) | H8: =IF(SHIPMENT_BUILDER!$H$8=4, SHIPMENT_BUILDER!$E$8, 0) | I8: =IF(SHIPMENT_BUILDER!$H$8=5, SHIPMENT_BUILDER!$E$8, 0) | J8: =IF(SHIPMENT_BUILDER!$H$8=6, SHIPMENT_BUILDER!$E$8, 0) | K8: =IF(SHIPMENT_BUILDER!$H$8=7, SHIPMENT_BUILDER!$E$8, 0) | L8: =IF(SHIPMENT_BUILDER!$H$8=8, SHIPMENT_BUILDER!$E$8, 0)
A9: =SHIPMENT_BUILDER!B9 | B9: =SHIPMENT_BUILDER!C9 | C9: Electroclean | D9: =SHIPMENT_BUILDER!E9 | E9: =IF(SHIPMENT_BUILDER!$H$9=1, SHIPMENT_BUILDER!$E$9, 0) | F9: =IF(SHIPMENT_BUILDER!$H$9=2, SHIPMENT_BUILDER!$E$9, 0) | G9: =IF(SHIPMENT_BUILDER!$H$9=3, SHIPMENT_BUILDER!$E$9, 0) | H9: =IF(SHIPMENT_BUILDER!$H$9=4, SHIPMENT_BUILDER!$E$9, 0) | I9: =IF(SHIPMENT_BUILDER!$H$9=5, SHIPMENT_BUILDER!$E$9, 0) | J9: =IF(SHIPMENT_BUILDER!$H$9=6, SHIPMENT_BUILDER!$E$9, 0) | K9: =IF(SHIPMENT_BUILDER!$H$9=7, SHIPMENT_BUILDER!$E$9, 0) | L9: =IF(SHIPMENT_BUILDER!$H$9=8, SHIPMENT_BUILDER!$E$9, 0)
A10: =SHIPMENT_BUILDER!B10 | B10: =SHIPMENT_BUILDER!C10 | C10: Electroclean | D10: =SHIPMENT_BUILDER!E10 | E10: =IF(SHIPMENT_BUILDER!$H$10=1, SHIPMENT_BUILDER!$E$10, 0) | F10: =IF(SHIPMENT_BUILDER!$H$10=2, SHIPMENT_BUILDER!$E$10, 0) | G10: =IF(SHIPMENT_BUILDER!$H$10=3, SHIPMENT_BUILDER!$E$10, 0) | H10: =IF(SHIPMENT_BUILDER!$H$10=4, SHIPMENT_BUILDER!$E$10, 0) | I10: =IF(SHIPMENT_BUILDER!$H$10=5, SHIPMENT_BUILDER!$E$10, 0) | J10: =IF(SHIPMENT_BUILDER!$H$10=6, SHIPMENT_BUILDER!$E$10, 0) | K10: =IF(SHIPMENT_BUILDER!$H$10=7, SHIPMENT_BUILDER!$E$10, 0) | L10: =IF(SHIPMENT_BUILDER!$H$10=8, SHIPMENT_BUILDER!$E$10, 0)
A11: =SHIPMENT_BUILDER!B11 | B11: =SHIPMENT_BUILDER!C11 | C11: Electroclean | D11: =SHIPMENT_BUILDER!E11 | E11: =IF(SHIPMENT_BUILDER!$H$11=1, SHIPMENT_BUILDER!$E$11, 0) | F11: =IF(SHIPMENT_BUILDER!$H$11=2, SHIPMENT_BUILDER!$E$11, 0) | G11: =IF(SHIPMENT_BUILDER!$H$11=3, SHIPMENT_BUILDER!$E$11, 0) | H11: =IF(SHIPMENT_BUILDER!$H$11=4, SHIPMENT_BUILDER!$E$11, 0) | I11: =IF(SHIPMENT_BUILDER!$H$11=5, SHIPMENT_BUILDER!$E$11, 0) | J11: =IF(SHIPMENT_BUILDER!$H$11=6, SHIPMENT_BUILDER!$E$11, 0) | K11: =IF(SHIPMENT_BUILDER!$H$11=7, SHIPMENT_BUILDER!$E$11, 0) | L11: =IF(SHIPMENT_BUILDER!$H$11=8, SHIPMENT_BUILDER!$E$11, 0)
A12: =SHIPMENT_BUILDER!B12 | B12: =SHIPMENT_BUILDER!C12 | C12: Electroclean | D12: =SHIPMENT_BUILDER!E12 | E12: =IF(SHIPMENT_BUILDER!$H$12=1, SHIPMENT_BUILDER!$E$12, 0) | F12: =IF(SHIPMENT_BUILDER!$H$12=2, SHIPMENT_BUILDER!$E$12, 0) | G12: =IF(SHIPMENT_BUILDER!$H$12=3, SHIPMENT_BUILDER!$E$12, 0) | H12: =IF(SHIPMENT_BUILDER!$H$12=4, SHIPMENT_BUILDER!$E$12, 0) | I12: =IF(SHIPMENT_BUILDER!$H$12=5, SHIPMENT_BUILDER!$E$12, 0) | J12: =IF(SHIPMENT_BUILDER!$H$12=6, SHIPMENT_BUILDER!$E$12, 0) | K12: =IF(SHIPMENT_BUILDER!$H$12=7, SHIPMENT_BUILDER!$E$12, 0) | L12: =IF(SHIPMENT_BUILDER!$H$12=8, SHIPMENT_BUILDER!$E$12, 0)
A13: =SHIPMENT_BUILDER!B13 | B13: =SHIPMENT_BUILDER!C13 | C13: Electroclean | D13: =SHIPMENT_BUILDER!E13 | E13: =IF(SHIPMENT_BUILDER!$H$13=1, SHIPMENT_BUILDER!$E$13, 0) | F13: =IF(SHIPMENT_BUILDER!$H$13=2, SHIPMENT_BUILDER!$E$13, 0) | G13: =IF(SHIPMENT_BUILDER!$H$13=3, SHIPMENT_BUILDER!$E$13, 0) | H13: =IF(SHIPMENT_BUILDER!$H$13=4, SHIPMENT_BUILDER!$E$13, 0) | I13: =IF(SHIPMENT_BUILDER!$H$13=5, SHIPMENT_BUILDER!$E$13, 0) | J13: =IF(SHIPMENT_BUILDER!$H$13=6, SHIPMENT_BUILDER!$E$13, 0) | K13: =IF(SHIPMENT_BUILDER!$H$13=7, SHIPMENT_BUILDER!$E$13, 0) | L13: =IF(SHIPMENT_BUILDER!$H$13=8, SHIPMENT_BUILDER!$E$13, 0)
A14: =SHIPMENT_BUILDER!B14 | B14: =SHIPMENT_BUILDER!C14 | C14: Electroclean | D14: =SHIPMENT_BUILDER!E14 | E14: =IF(SHIPMENT_BUILDER!$H$14=1, SHIPMENT_BUILDER!$E$14, 0) | F14: =IF(SHIPMENT_BUILDER!$H$14=2, SHIPMENT_BUILDER!$E$14, 0) | G14: =IF(SHIPMENT_BUILDER!$H$14=3, SHIPMENT_BUILDER!$E$14, 0) | H14: =IF(SHIPMENT_BUILDER!$H$14=4, SHIPMENT_BUILDER!$E$14, 0) | I14: =IF(SHIPMENT_BUILDER!$H$14=5, SHIPMENT_BUILDER!$E$14, 0) | J14: =IF(SHIPMENT_BUILDER!$H$14=6, SHIPMENT_BUILDER!$E$14, 0) | K14: =IF(SHIPMENT_BUILDER!$H$14=7, SHIPMENT_BUILDER!$E$14, 0) | L14: =IF(SHIPMENT_BUILDER!$H$14=8, SHIPMENT_BUILDER!$E$14, 0)
A15: =SHIPMENT_BUILDER!B15 | B15: =SHIPMENT_BUILDER!C15 | C15: Electroclean | D15: =SHIPMENT_BUILDER!E15 | E15: =IF(SHIPMENT_BUILDER!$H$15=1, SHIPMENT_BUILDER!$E$15, 0) | F15: =IF(SHIPMENT_BUILDER!$H$15=2, SHIPMENT_BUILDER!$E$15, 0) | G15: =IF(SHIPMENT_BUILDER!$H$15=3, SHIPMENT_BUILDER!$E$15, 0) | H15: =IF(SHIPMENT_BUILDER!$H$15=4, SHIPMENT_BUILDER!$E$15, 0) | I15: =IF(SHIPMENT_BUILDER!$H$15=5, SHIPMENT_BUILDER!$E$15, 0) | J15: =IF(SHIPMENT_BUILDER!$H$15=6, SHIPMENT_BUILDER!$E$15, 0) | K15: =IF(SHIPMENT_BUILDER!$H$15=7, SHIPMENT_BUILDER!$E$15, 0) | L15: =IF(SHIPMENT_BUILDER!$H$15=8, SHIPMENT_BUILDER!$E$15, 0)
A16: =SHIPMENT_BUILDER!B16 | B16: =SHIPMENT_BUILDER!C16 | C16: Electroclean | D16: =SHIPMENT_BUILDER!E16 | E16: =IF(SHIPMENT_BUILDER!$H$16=1, SHIPMENT_BUILDER!$E$16, 0) | F16: =IF(SHIPMENT_BUILDER!$H$16=2, SHIPMENT_BUILDER!$E$16, 0) | G16: =IF(SHIPMENT_BUILDER!$H$16=3, SHIPMENT_BUILDER!$E$16, 0) | H16: =IF(SHIPMENT_BUILDER!$H$16=4, SHIPMENT_BUILDER!$E$16, 0) | I16: =IF(SHIPMENT_BUILDER!$H$16=5, SHIPMENT_BUILDER!$E$16, 0) | J16: =IF(SHIPMENT_BUILDER!$H$16=6, SHIPMENT_BUILDER!$E$16, 0) | K16: =IF(SHIPMENT_BUILDER!$H$16=7, SHIPMENT_BUILDER!$E$16, 0) | L16: =IF(SHIPMENT_BUILDER!$H$16=8, SHIPMENT_BUILDER!$E$16, 0)
A17: =SHIPMENT_BUILDER!B17 | B17: =SHIPMENT_BUILDER!C17 | C17: Electroclean | D17: =SHIPMENT_BUILDER!E17 | E17: =IF(SHIPMENT_BUILDER!$H$17=1, SHIPMENT_BUILDER!$E$17, 0) | F17: =IF(SHIPMENT_BUILDER!$H$17=2, SHIPMENT_BUILDER!$E$17, 0) | G17: =IF(SHIPMENT_BUILDER!$H$17=3, SHIPMENT_BUILDER!$E$17, 0) | H17: =IF(SHIPMENT_BUILDER!$H$17=4, SHIPMENT_BUILDER!$E$17, 0) | I17: =IF(SHIPMENT_BUILDER!$H$17=5, SHIPMENT_BUILDER!$E$17, 0) | J17: =IF(SHIPMENT_BUILDER!$H$17=6, SHIPMENT_BUILDER!$E$17, 0) | K17: =IF(SHIPMENT_BUILDER!$H$17=7, SHIPMENT_BUILDER!$E$17, 0) | L17: =IF(SHIPMENT_BUILDER!$H$17=8, SHIPMENT_BUILDER!$E$17, 0)
A18: =SHIPMENT_BUILDER!B18 | B18: =SHIPMENT_BUILDER!C18 | C18: Electroclean | D18: =SHIPMENT_BUILDER!E18 | E18: =IF(SHIPMENT_BUILDER!$H$18=1, SHIPMENT_BUILDER!$E$18, 0) | F18: =IF(SHIPMENT_BUILDER!$H$18=2, SHIPMENT_BUILDER!$E$18, 0) | G18: =IF(SHIPMENT_BUILDER!$H$18=3, SHIPMENT_BUILDER!$E$18, 0) | H18: =IF(SHIPMENT_BUILDER!$H$18=4, SHIPMENT_BUILDER!$E$18, 0) | I18: =IF(SHIPMENT_BUILDER!$H$18=5, SHIPMENT_BUILDER!$E$18, 0) | J18: =IF(SHIPMENT_BUILDER!$H$18=6, SHIPMENT_BUILDER!$E$18, 0) | K18: =IF(SHIPMENT_BUILDER!$H$18=7, SHIPMENT_BUILDER!$E$18, 0) | L18: =IF(SHIPMENT_BUILDER!$H$18=8, SHIPMENT_BUILDER!$E$18, 0)
A19: =SHIPMENT_BUILDER!B19 | B19: =SHIPMENT_BUILDER!C19 | C19: Electroclean | D19: =SHIPMENT_BUILDER!E19 | E19: =IF(SHIPMENT_BUILDER!$H$19=1, SHIPMENT_BUILDER!$E$19, 0) | F19: =IF(SHIPMENT_BUILDER!$H$19=2, SHIPMENT_BUILDER!$E$19, 0) | G19: =IF(SHIPMENT_BUILDER!$H$19=3, SHIPMENT_BUILDER!$E$19, 0) | H19: =IF(SHIPMENT_BUILDER!$H$19=4, SHIPMENT_BUILDER!$E$19, 0) | I19: =IF(SHIPMENT_BUILDER!$H$19=5, SHIPMENT_BUILDER!$E$19, 0) | J19: =IF(SHIPMENT_BUILDER!$H$19=6, SHIPMENT_BUILDER!$E$19, 0) | K19: =IF(SHIPMENT_BUILDER!$H$19=7, SHIPMENT_BUILDER!$E$19, 0) | L19: =IF(SHIPMENT_BUILDER!$H$19=8, SHIPMENT_BUILDER!$E$19, 0)
A20: =SHIPMENT_BUILDER!B20 | B20: =SHIPMENT_BUILDER!C20 | C20: Electroclean | D20: =SHIPMENT_BUILDER!E20 | E20: =IF(SHIPMENT_BUILDER!$H$20=1, SHIPMENT_BUILDER!$E$20, 0) | F20: =IF(SHIPMENT_BUILDER!$H$20=2, SHIPMENT_BUILDER!$E$20, 0) | G20: =IF(SHIPMENT_BUILDER!$H$20=3, SHIPMENT_BUILDER!$E$20, 0) | H20: =IF(SHIPMENT_BUILDER!$H$20=4, SHIPMENT_BUILDER!$E$20, 0) | I20: =IF(SHIPMENT_BUILDER!$H$20=5, SHIPMENT_BUILDER!$E$20, 0) | J20: =IF(SHIPMENT_BUILDER!$H$20=6, SHIPMENT_BUILDER!$E$20, 0) | K20: =IF(SHIPMENT_BUILDER!$H$20=7, SHIPMENT_BUILDER!$E$20, 0) | L20: =IF(SHIPMENT_BUILDER!$H$20=8, SHIPMENT_BUILDER!$E$20, 0)
A21: =SHIPMENT_BUILDER!B21 | B21: =SHIPMENT_BUILDER!C21 | C21: Electroclean | D21: =SHIPMENT_BUILDER!E21 | E21: =IF(SHIPMENT_BUILDER!$H$21=1, SHIPMENT_BUILDER!$E$21, 0) | F21: =IF(SHIPMENT_BUILDER!$H$21=2, SHIPMENT_BUILDER!$E$21, 0) | G21: =IF(SHIPMENT_BUILDER!$H$21=3, SHIPMENT_BUILDER!$E$21, 0) | H21: =IF(SHIPMENT_BUILDER!$H$21=4, SHIPMENT_BUILDER!$E$21, 0) | I21: =IF(SHIPMENT_BUILDER!$H$21=5, SHIPMENT_BUILDER!$E$21, 0) | J21: =IF(SHIPMENT_BUILDER!$H$21=6, SHIPMENT_BUILDER!$E$21, 0) | K21: =IF(SHIPMENT_BUILDER!$H$21=7, SHIPMENT_BUILDER!$E$21, 0) | L21: =IF(SHIPMENT_BUILDER!$H$21=8, SHIPMENT_BUILDER!$E$21, 0)
A22: =SHIPMENT_BUILDER!B22 | B22: =SHIPMENT_BUILDER!C22 | C22: Electroclean | D22: =SHIPMENT_BUILDER!E22 | E22: =IF(SHIPMENT_BUILDER!$H$22=1, SHIPMENT_BUILDER!$E$22, 0) | F22: =IF(SHIPMENT_BUILDER!$H$22=2, SHIPMENT_BUILDER!$E$22, 0) | G22: =IF(SHIPMENT_BUILDER!$H$22=3, SHIPMENT_BUILDER!$E$22, 0) | H22: =IF(SHIPMENT_BUILDER!$H$22=4, SHIPMENT_BUILDER!$E$22, 0) | I22: =IF(SHIPMENT_BUILDER!$H$22=5, SHIPMENT_BUILDER!$E$22, 0) | J22: =IF(SHIPMENT_BUILDER!$H$22=6, SHIPMENT_BUILDER!$E$22, 0) | K22: =IF(SHIPMENT_BUILDER!$H$22=7, SHIPMENT_BUILDER!$E$22, 0) | L22: =IF(SHIPMENT_BUILDER!$H$22=8, SHIPMENT_BUILDER!$E$22, 0)
A23: =SHIPMENT_BUILDER!B23 | B23: =SHIPMENT_BUILDER!C23 | C23: Electroclean | D23: =SHIPMENT_BUILDER!E23 | E23: =IF(SHIPMENT_BUILDER!$H$23=1, SHIPMENT_BUILDER!$E$23, 0) | F23: =IF(SHIPMENT_BUILDER!$H$23=2, SHIPMENT_BUILDER!$E$23, 0) | G23: =IF(SHIPMENT_BUILDER!$H$23=3, SHIPMENT_BUILDER!$E$23, 0) | H23: =IF(SHIPMENT_BUILDER!$H$23=4, SHIPMENT_BUILDER!$E$23, 0) | I23: =IF(SHIPMENT_BUILDER!$H$23=5, SHIPMENT_BUILDER!$E$23, 0) | J23: =IF(SHIPMENT_BUILDER!$H$23=6, SHIPMENT_BUILDER!$E$23, 0) | K23: =IF(SHIPMENT_BUILDER!$H$23=7, SHIPMENT_BUILDER!$E$23, 0) | L23: =IF(SHIPMENT_BUILDER!$H$23=8, SHIPMENT_BUILDER!$E$23, 0)
A24: =SHIPMENT_BUILDER!B24 | B24: =SHIPMENT_BUILDER!C24 | C24: Electroclean | D24: =SHIPMENT_BUILDER!E24 | E24: =IF(SHIPMENT_BUILDER!$H$24=1, SHIPMENT_BUILDER!$E$24, 0) | F24: =IF(SHIPMENT_BUILDER!$H$24=2, SHIPMENT_BUILDER!$E$24, 0) | G24: =IF(SHIPMENT_BUILDER!$H$24=3, SHIPMENT_BUILDER!$E$24, 0) | H24: =IF(SHIPMENT_BUILDER!$H$24=4, SHIPMENT_BUILDER!$E$24, 0) | I24: =IF(SHIPMENT_BUILDER!$H$24=5, SHIPMENT_BUILDER!$E$24, 0) | J24: =IF(SHIPMENT_BUILDER!$H$24=6, SHIPMENT_BUILDER!$E$24, 0) | K24: =IF(SHIPMENT_BUILDER!$H$24=7, SHIPMENT_BUILDER!$E$24, 0) | L24: =IF(SHIPMENT_BUILDER!$H$24=8, SHIPMENT_BUILDER!$E$24, 0)
A25: =SHIPMENT_BUILDER!B25 | B25: =SHIPMENT_BUILDER!C25 | C25: Electroclean | D25: =SHIPMENT_BUILDER!E25 | E25: =IF(SHIPMENT_BUILDER!$H$25=1, SHIPMENT_BUILDER!$E$25, 0) | F25: =IF(SHIPMENT_BUILDER!$H$25=2, SHIPMENT_BUILDER!$E$25, 0) | G25: =IF(SHIPMENT_BUILDER!$H$25=3, SHIPMENT_BUILDER!$E$25, 0) | H25: =IF(SHIPMENT_BUILDER!$H$25=4, SHIPMENT_BUILDER!$E$25, 0) | I25: =IF(SHIPMENT_BUILDER!$H$25=5, SHIPMENT_BUILDER!$E$25, 0) | J25: =IF(SHIPMENT_BUILDER!$H$25=6, SHIPMENT_BUILDER!$E$25, 0) | K25: =IF(SHIPMENT_BUILDER!$H$25=7, SHIPMENT_BUILDER!$E$25, 0) | L25: =IF(SHIPMENT_BUILDER!$H$25=8, SHIPMENT_BUILDER!$E$25, 0)
