Workbook

Sheet ROUTE_CONFIG
A1: ROUTE CONFIGURATION - Transport Physics
A2: Define transport modes and warehouse costs. Yellow cells are editable.
A4: TABLE 1: TRANSPORT MODES
A5: Mode | B5: Lead Time (Fortnights) | C5: Cost Per Unit ($)
A6: Train | B6: 0 | C6: 0
A7: Truck | B7: 0 | C7: 0
A8: Plane | B8: 0 | C8: 0
A11: TABLE 2: WAREHOUSE CONFIGURATION
A12: Zone | B12: Current Capacity | C12: Cost Per Module | D12: Capacity Per Module
A13: Center | B13: 4800 | C13: 0 | D13: 0
A14: West | B14: 2500 | C14: 0 | D14: 0
A15: North | B15: 2000 | C15: 0 | D15: 0
A16: East | B16: 0 | C16: 0 | D16: 0
A17: South | B17: 0 | C17: 0 | D17: 0

Sheet INVENTORY_TETRIS
A1: INVENTORY TETRIS - Zone-by-Zone Balance
A2: Balance inventory using shipments. Watch for STOCKOUT (red) and OVERFLOW (purple) flags.
A4: ═══ CENTER ZONE (Capacity: 4,800) ═══
A5: Opening Inventory | B5: 3410 | D5: Capacity | E5: 4800 | G5: Rent Modules? | H5: 0
A7: Fortnight | B7: Production | C7: Sales | D7: Outgoing | E7: Incoming | F7: Projected Inv | G7: Flag
A8: FN1 | B8: 0 | C8: 0 | D8: 0 | E8: 0 | F8: =$B$5+B8+E8-D8-C8 | G8: =IF(F8<0,"STOCKOUT: SHIP HERE!",IF(F8>$E$5+(H$5*ROUTE_CONFIG!$D$12),"OVERFLOW: RENT!","OK"))
A9: FN2 | B9: 0 | C9: 0 | D9: 0 | E9: 0 | F9: =F8+B9+E9-D9-C9 | G9: =IF(F9<0,"STOCKOUT: SHIP HERE!",IF(F9>$E$5+(H$5*ROUTE_CONFIG!$D$12),"OVERFLOW: RENT!","OK"))
A10: FN3 | B10: 0 | C10: 0 | D10: 0 | E10: 0 | F10: =F9+B10+E10-D10-C10 | G10: =IF(F10<0,"STOCKOUT: SHIP HERE!",IF(F10>$E$5+(H$5*ROUTE_CONFIG!$D$12),"OVERFLOW: RENT!","OK"))
A11: FN4 | B11: 0 | C11: 0 | D11: 0 | E11: 0 | F11: =F10+B11+E11-D11-C11 | G11: =IF(F11<0,"STOCKOUT: SHIP HERE!",IF(F11>$E$5+(H$5*ROUTE_CONFIG!$D$12),"OVERFLOW: RENT!","OK"))
A12: FN5 | B12: 0 | C12: 0 | D12: 0 | E12: 0 | F12: =F11+B12+E12-D12-C12 | G12: =IF(F12<0,"STOCKOUT: SHIP HERE!",IF(F12>$E$5+(H$5*ROUTE_CONFIG!$D$12),"OVERFLOW: RENT!","OK"))
A13: FN6 | B13: 0 | C13: 0 | D13: 0 | E13: 0 | F13: =F12+B13+E13-D13-C13 | G13: =IF(F13<0,"STOCKOUT: SHIP HERE!",IF(F13>$E$5+(H$5*ROUTE_CONFIG!$D$12),"OVERFLOW: RENT!","OK"))
A14: FN7 | B14: 0 | C14: 0 | D14: 0 | E14: 0 | F14: =F13+B14+E14-D14-C14 | G14: =IF(F14<0,"STOCKOUT: SHIP HERE!",IF(F14>$E$5+(H$5*ROUTE_CONFIG!$D$12),"OVERFLOW: RENT!","OK"))
A15: FN8 | B15: 0 | C15: 0 | D15: 0 | E15: 0 | F15: =F14+B15+E15-D15-C15 | G15: =IF(F15<0,"STOCKOUT: SHIP HERE!",IF(F15>$E$5+(H$5*ROUTE_CONFIG!$D$12),"OVERFLOW: RENT!","OK"))
A18: ═══ WEST ZONE (Capacity: 2,500) ═══
A19: Opening Inventory | B19: 1886 | D19: Capacity | E19: 2500 | G19: Rent Modules? | H19: 0
A21: Fortnight | B21: Production | C21: Sales | D21: Outgoing | E21: Incoming | F21: Projected Inv | G21: Flag
A22: FN1 | B22: 0 | C22: 0 | D22: 0 | E22: 0 | F22: =$B$19+B22+E22-D22-C22 | G22: =IF(F22<0,"STOCKOUT: SHIP HERE!",IF(F22>$E$19+(H$19*ROUTE_CONFIG!$D$13),"OVERFLOW: RENT!","OK"))
A23: FN2 | B23: 0 | C23: 0 | D23: 0 | E23: 0 | F23: =F22+B23+E23-D23-C23 | G23: =IF(F23<0,"STOCKOUT: SHIP HERE!",IF(F23>$E$19+(H$19*ROUTE_CONFIG!$D$13),"OVERFLOW: RENT!","OK"))
A24: FN3 | B24: 0 | C24: 0 | D24: 0 | E24: 0 | F24: =F23+B24+E24-D24-C24 | G24: =IF(F24<0,"STOCKOUT: SHIP HERE!",IF(F24>$E$19+(H$19*ROUTE_CONFIG!$D$13),"OVERFLOW: RENT!","OK"))
A25: FN4 | B25: 0 | C25: 0 | D25: 0 | E25: 0 | F25: =F24+B25+E25-D25-C25 | G25: =IF(F25<0,"STOCKOUT: SHIP HERE!",IF(F25>$E$19+(H$19*ROUTE_CONFIG!$D$13),"OVERFLOW: RENT!","OK"))
A26: FN5 | B26: 0 | C26: 0 | D26: 0 | E26: 0 | F26: =F25+B26+E26-D26-C26 | G26: =IF(F26<0,"STOCKOUT: SHIP HERE!",IF(F26>$E$19+(H$19*ROUTE_CONFIG!$D$13),"OVERFLOW: RENT!","OK"))
A27: FN6 | B27: 0 | C27: 0 | D27: 0 | E27: 0 | F27: =F26+B27+E27-D27-C27 | G27: =IF(F27<0,"STOCKOUT: SHIP HERE!",IF(F27>$E$19+(H$19*ROUTE_CONFIG!$D$13),"OVERFLOW: RENT!","OK"))
A28: FN7 | B28: 0 | C28: 0 | D28: 0 | E28: 0 | F28: =F27+B28+E28-D28-C28 | G28: =IF(F28<0,"STOCKOUT: SHIP HERE!",IF(F28>$E$19+(H$19*ROUTE_CONFIG!$D$13),"OVERFLOW: RENT!","OK"))
A29: FN8 | B29: 0 | C29: 0 | D29: 0 | E29: 0 | F29: =F28+B29+E29-D29-C29 | G29: =IF(F29<0,"STOCKOUT: SHIP HERE!",IF(F29>$E$19+(H$19*ROUTE_CONFIG!$D$13),"OVERFLOW: RENT!","OK"))
A32: ═══ NORTH ZONE (Capacity: 2,000) ═══
A33: Opening Inventory | B33: 1720 | D33: Capacity | E33: 2000 | G33: Rent Modules? | H33: 0
A35: Fortnight | B35: Production | C35: Sales | D35: Outgoing | E35: Incoming | F35: Projected Inv | G35: Flag
A36: FN1 | B36: 0 | C36: 0 | D36: 0 | E36: 0 | F36: =$B$33+B36+E36-D36-C36 | G36: =IF(F36<0,"STOCKOUT: SHIP HERE!",IF(F36>$E$33+(H$33*ROUTE_CONFIG!$D$14),"OVERFLOW: RENT!","OK"))
A37: FN2 | B37: 0 | C37: 0 | D37: 0 | E37: 0 | F37: =F36+B37+E37-D37-C37 | G37: =IF(F37<0,"STOCKOUT: SHIP HERE!",IF(F37>$E$33+(H$33*ROUTE_CONFIG!$D$14),"OVERFLOW: RENT!","OK"))
A38: FN3 | B38: 0 | C38: 0 | D38: 0 | E38: 0 | F38: =F37+B38+E38-D38-C38 | G38: =IF(F38<0,"STOCKOUT: SHIP HERE!",IF(F38>$E$33+(H$33*ROUTE_CONFIG!$D$14),"OVERFLOW: RENT!","OK"))
A39: FN4 | B39: 0 | C39: 0 | D39: 0 | E39: 0 | F39: =F38+B39+E39-D39-C39 | G39: =IF(F39<0,"STOCKOUT: SHIP HERE!",IF(F39>$E$33+(H$33*ROUTE_CONFIG!$D$14),"OVERFLOW: RENT!","OK"))
A40: FN5 | B40: 0 | C40: 0 | D40: 0 | E40: 0 | F40: =F39+B40+E40-D40-C40 | G40: =IF(F40<0,"STOCKOUT: SHIP HERE!",IF(F40>$E$33+(H$33*ROUTE_CONFIG!$D$14),"OVERFLOW: RENT!","OK"))
A41: FN6 | B41: 0 | C41: 0 | D41: 0 | E41: 0 | F41: =F40+B41+E41-D41-C41 | G41: =IF(F41<0,"STOCKOUT: SHIP HERE!",IF(F41>$E$33+(H$33*ROUTE_CONFIG!$D$14),"OVERFLOW: RENT!","OK"))
A42: FN7 | B42: 0 | C42: 0 | D42: 0 | E42: 0 | F42: =F41+B42+E42-D42-C42 | G42: =IF(F42<0,"STOCKOUT: SHIP HERE!",IF(F42>$E$33+(H$33*ROUTE_CONFIG!$D$14),"OVERFLOW: RENT!","OK"))
A43: FN8 | B43: 0 | C43: 0 | D43: 0 | E43: 0 | F43: =F42+B43+E43-D43-C43 | G43: =IF(F43<0,"STOCKOUT: SHIP HERE!",IF(F43>$E$33+(H$33*ROUTE_CONFIG!$D$14),"OVERFLOW: RENT!","OK"))
A46: ═══ EAST ZONE (Capacity: 0) ═══
A47: Opening Inventory | B47: 0 | D47: Capacity | E47: 0 | G47: Rent Modules? | H47: 0
A49: Fortnight | B49: Production | C49: Sales | D49: Outgoing | E49: Incoming | F49: Projected Inv | G49: Flag
A50: FN1 | B50: 0 | C50: 0 | D50: 0 | E50: 0 | F50: =$B$47+B50+E50-D50-C50 | G50: =IF(F50<0,"STOCKOUT: SHIP HERE!",IF(F50>$E$47+(H$47*ROUTE_CONFIG!$D$15),"OVERFLOW: RENT!","OK"))
A51: FN2 | B51: 0 | C51: 0 | D51: 0 | E51: 0 | F51: =F50+B51+E51-D51-C51 | G51: =IF(F51<0,"STOCKOUT: SHIP HERE!",IF(F51>$E$47+(H$47*ROUTE_CONFIG!$D$15),"OVERFLOW: RENT!","OK"))
...

Sheet SHIPMENT_BUILDER
A1: SHIPMENT BUILDER - Plan Your Transfers
A2: Add shipments here. MANUALLY update Outgoing/Incoming in INVENTORY_TETRIS (shifted by Lead Time).
A4: IMPORTANT: After entering shipments here, update INVENTORY_TETRIS Tab 2:
A5: • Add NEGATIVE quantity to Origin zone's 'Outgoing' column in the ORDER fortnight
A6: • Add POSITIVE quantity to Destination zone's 'Incoming' column in ARRIVAL fortnight (Order + Lead Time)
A8: SHIPMENT SCHEDULE
A9: # | B9: Fortnight | C9: Origin | D9: Destination | E9: Material | F9: Mode | G9: Quantity | H9: Lead Time | I9: Arrival FN
A10: 1 | E10: Electroclean | F10: Truck | H10: =IF(F10="Train",ROUTE_CONFIG!$B$6,IF(F10="Truck",ROUTE_CONFIG!$B$7,ROUTE_CONFIG!$B$8)) | I10: =IF(B10<>"",B10+H10,"")
A11: 2 | E11: Electroclean | F11: Truck | H11: =IF(F11="Train",ROUTE_CONFIG!$B$6,IF(F11="Truck",ROUTE_CONFIG!$B$7,ROUTE_CONFIG!$B$8)) | I11: =IF(B11<>"",B11+H11,"")
A12: 3 | E12: Electroclean | F12: Truck | H12: =IF(F12="Train",ROUTE_CONFIG!$B$6,IF(F12="Truck",ROUTE_CONFIG!$B$7,ROUTE_CONFIG!$B$8)) | I12: =IF(B12<>"",B12+H12,"")
A13: 4 | E13: Electroclean | F13: Truck | H13: =IF(F13="Train",ROUTE_CONFIG!$B$6,IF(F13="Truck",ROUTE_CONFIG!$B$7,ROUTE_CONFIG!$B$8)) | I13: =IF(B13<>"",B13+H13,"")
A14: 5 | E14: Electroclean | F14: Truck | H14: =IF(F14="Train",ROUTE_CONFIG!$B$6,IF(F14="Truck",ROUTE_CONFIG!$B$7,ROUTE_CONFIG!$B$8)) | I14: =IF(B14<>"",B14+H14,"")
A15: 6 | E15: Electroclean | F15: Truck | H15: =IF(F15="Train",ROUTE_CONFIG!$B$6,IF(F15="Truck",ROUTE_CONFIG!$B$7,ROUTE_CONFIG!$B$8)) | I15: =IF(B15<>"",B15+H15,"")
A16: 7 | E16: Electroclean | F16: Truck | H16: =IF(F16="Train",ROUTE_CONFIG!$B$6,IF(F16="Truck",ROUTE_CONFIG!$B$7,ROUTE_CONFIG!$B$8)) | I16: =IF(B16<>"",B16+H16,"")
A17: 8 | E17: Electroclean | F17: Truck | H17: =IF(F17="Train",ROUTE_CONFIG!$B$6,IF(F17="Truck",ROUTE_CONFIG!$B$7,ROUTE_CONFIG!$B$8)) | I17: =IF(B17<>"",B17+H17,"")
A18: 9 | E18: Electroclean | F18: Truck | H18: =IF(F18="Train",ROUTE_CONFIG!$B$6,IF(F18="Truck",ROUTE_CONFIG!$B$7,ROUTE_CONFIG!$B$8)) | I18: =IF(B18<>"",B18+H18,"")
A19: 10 | E19: Electroclean | F19: Truck | H19: =IF(F19="Train",ROUTE_CONFIG!$B$6,IF(F19="Truck",ROUTE_CONFIG!$B$7,ROUTE_CONFIG!$B$8)) | I19: =IF(B19<>"",B19+H19,"")

Sheet UPLOAD_READY_LOGISTICS
A1: LOGISTICS DECISIONS - ExSim Upload Format (Side-by-Side)
A2: Copy these values to ExSim Logistics upload
A4: Warehouses | F4: Shipments
A5: Zone | B5: Buy Modules | C5: Rent Modules | F5: Fortnight | G5: Origin | H5: Destination | I5: Material | J5: Transport | K5: Quantity
A6: Center | B6: 0 | C6: =INVENTORY_TETRIS!H5 | F6: =SHIPMENT_BUILDER!B10 | G6: =SHIPMENT_BUILDER!C10 | H6: =SHIPMENT_BUILDER!D10 | I6: =SHIPMENT_BUILDER!E10 | J6: =SHIPMENT_BUILDER!F10 | K6: =SHIPMENT_BUILDER!G10
A7: West | B7: 0 | C7: =INVENTORY_TETRIS!H19 | F7: =SHIPMENT_BUILDER!B11 | G7: =SHIPMENT_BUILDER!C11 | H7: =SHIPMENT_BUILDER!D11 | I7: =SHIPMENT_BUILDER!E11 | J7: =SHIPMENT_BUILDER!F11 | K7: =SHIPMENT_BUILDER!G11
A8: North | B8: 0 | C8: =INVENTORY_TETRIS!H33 | F8: =SHIPMENT_BUILDER!B12 | G8: =SHIPMENT_BUILDER!C12 | H8: =SHIPMENT_BUILDER!D12 | I8: =SHIPMENT_BUILDER!E12 | J8: =SHIPMENT_BUILDER!F12 | K8: =SHIPMENT_BUILDER!G12
A9: East | B9: 0 | C9: =INVENTORY_TETRIS!H47 | F9: =SHIPMENT_BUILDER!B13 | G9: =SHIPMENT_BUILDER!C13 | H9: =SHIPMENT_BUILDER!D13 | I9: =SHIPMENT_BUILDER!E13 | J9: =SHIPMENT_BUILDER!F13 | K9: =SHIPMENT_BUILDER!G13
A10: South | B10: 0 | C10: =INVENTORY_TETRIS!H61 | F10: =SHIPMENT_BUILDER!B14 | G10: =SHIPMENT_BUILDER!C14 | H10: =SHIPMENT_BUILDER!D14 | I10: =SHIPMENT_BUILDER!E14 | J10: =SHIPMENT_BUILDER!F14 | K10: =SHIPMENT_BUILDER!G14
F11: =SHIPMENT_BUILDER!B15 | G11: =SHIPMENT_BUILDER!C15 | H11: =SHIPMENT_BUILDER!D15 | I11: =SHIPMENT_BUILDER!E15 | J11: =SHIPMENT_BUILDER!F15 | K11: =SHIPMENT_BUILDER!G15
F12: =SHIPMENT_BUILDER!B16 | G12: =SHIPMENT_BUILDER!C16 | H12: =SHIPMENT_BUILDER!D16 | I12: =SHIPMENT_BUILDER!E16 | J12: =SHIPMENT_BUILDER!F16 | K12: =SHIPMENT_BUILDER!G16
F13: =SHIPMENT_BUILDER!B17 | G13: =SHIPMENT_BUILDER!C17 | H13: =SHIPMENT_BUILDER!D17 | I13: =SHIPMENT_BUILDER!E17 | J13: =SHIPMENT_BUILDER!F17 | K13: =SHIPMENT_BUILDER!G17
F14: =SHIPMENT_BUILDER!B18 | G14: =SHIPMENT_BUILDER!C18 | H14: =SHIPMENT_BUILDER!D18 | I14: =SHIPMENT_BUILDER!E18 | J14: =SHIPMENT_BUILDER!F18 | K14: =SHIPMENT_BUILDER!G18
F15: =SHIPMENT_BUILDER!B19 | G15: =SHIPMENT_BUILDER!C19 | H15: =SHIPMENT_BUILDER!D19 | I15: =SHIPMENT_BUILDER!E19 | J15: =SHIPMENT_BUILDER!F19 | K15: =SHIPMENT_BUILDER!G19
