Workbook

Sheet ZONE_CALCULATORS
A1: ZONE-SPECIFIC PRODUCTION CALCULATORS
A2: Each zone has its own resources. Resources in Center do NOT count towards West capacity.
A4: ═══ CENTER ZONE ═══
A5: Machines in Zone | B5: 156
A6: Material Stock (Part A) | B6: 94
A7: Workers in Zone | B7: 219
A8: Nominal Rate/Machine | B8: 200
A10: Fortnight | B10: Target | C10: Overtime | D10: Local Capacity | E10: Material Cap | F10: REAL OUTPUT | G10: Shipment?
A11: FN1 | B11: 500 | C11: N | D11: =$B$5*$B$8 | E11: =$B$6 | F11: =MIN(B11,D11,E11) | G11: =IF(B11>E11, "SHIPMENT NEEDED!", "OK")
A12: FN2 | B12: 500 | C12: N | D12: =$B$5*$B$8 | E12: =$B$6 | F12: =MIN(B12,D12,E12) | G12: =IF(B12>E12, "SHIPMENT NEEDED!", "OK")
A13: FN3 | B13: 500 | C13: N | D13: =$B$5*$B$8 | E13: =$B$6 | F13: =MIN(B13,D13,E13) | G13: =IF(B13>E13, "SHIPMENT NEEDED!", "OK")
A14: FN4 | B14: 500 | C14: N | D14: =$B$5*$B$8 | E14: =$B$6 | F14: =MIN(B14,D14,E14) | G14: =IF(B14>E14, "SHIPMENT NEEDED!", "OK")
A15: FN5 | B15: 500 | C15: N | D15: =$B$5*$B$8 | E15: =$B$6 | F15: =MIN(B15,D15,E15) | G15: =IF(B15>E15, "SHIPMENT NEEDED!", "OK")
A16: FN6 | B16: 500 | C16: N | D16: =$B$5*$B$8 | E16: =$B$6 | F16: =MIN(B16,D16,E16) | G16: =IF(B16>E16, "SHIPMENT NEEDED!", "OK")
A17: FN7 | B17: 500 | C17: N | D17: =$B$5*$B$8 | E17: =$B$6 | F17: =MIN(B17,D17,E17) | G17: =IF(B17>E17, "SHIPMENT NEEDED!", "OK")
A18: FN8 | B18: 500 | C18: N | D18: =$B$5*$B$8 | E18: =$B$6 | F18: =MIN(B18,D18,E18) | G18: =IF(B18>E18, "SHIPMENT NEEDED!", "OK")
A19: TOTAL | B19: =SUM(B11:B18) | F19: =SUM(F11:F18)
A22: ═══ WEST ZONE ═══
A23: Machines in Zone | B23: 0
A24: Material Stock (Part A) | B24: 36
A25: Workers in Zone | B25: 71
A26: Nominal Rate/Machine | B26: 200
A28: Fortnight | B28: Target | C28: Overtime | D28: Local Capacity | E28: Material Cap | F28: REAL OUTPUT | G28: Shipment?
A29: FN1 | B29: 0 | C29: N | D29: =$B$23*$B$26 | E29: =$B$24 | F29: =MIN(B29,D29,E29) | G29: =IF(B29>E29, "SHIPMENT NEEDED!", "OK")
A30: FN2 | B30: 0 | C30: N | D30: =$B$23*$B$26 | E30: =$B$24 | F30: =MIN(B30,D30,E30) | G30: =IF(B30>E30, "SHIPMENT NEEDED!", "OK")
A31: FN3 | B31: 0 | C31: N | D31: =$B$23*$B$26 | E31: =$B$24 | F31: =MIN(B31,D31,E31) | G31: =IF(B31>E31, "SHIPMENT NEEDED!", "OK")
A32: FN4 | B32: 0 | C32: N | D32: =$B$23*$B$26 | E32: =$B$24 | F32: =MIN(B32,D32,E32) | G32: =IF(B32>E32, "SHIPMENT NEEDED!", "OK")
A33: FN5 | B33: 0 | C33: N | D33: =$B$23*$B$26 | E33: =$B$24 | F33: =MIN(B33,D33,E33) | G33: =IF(B33>E33, "SHIPMENT NEEDED!", "OK")
A34: FN6 | B34: 0 | C34: N | D34: =$B$23*$B$26 | E34: =$B$24 | F34: =MIN(B34,D34,E34) | G34: =IF(B34>E34, "SHIPMENT NEEDED!", "OK")
A35: FN7 | B35: 0 | C35: N | D35: =$B$23*$B$26 | E35: =$B$24 | F35: =MIN(B35,D35,E35) | G35: =IF(B35>E35, "SHIPMENT NEEDED!", "OK")
A36: FN8 | B36: 0 | C36: N | D36: =$B$23*$B$26 | E36: =$B$24 | F36: =MIN(B36,D36,E36) | G36: =IF(B36>E36, "SHIPMENT NEEDED!", "OK")
A37: TOTAL | B37: =SUM(B29:B36) | F37: =SUM(F29:F36)
A40: ═══ NORTH ZONE ═══
A41: Machines in Zone | B41: 0
A42: Material Stock (Part A) | B42: 0
A43: Workers in Zone | B43: 0
A44: Nominal Rate/Machine | B44: 200
A46: Fortnight | B46: Target | C46: Overtime | D46: Local Capacity | E46: Material Cap | F46: REAL OUTPUT | G46: Shipment?
A47: FN1 | B47: 0 | C47: N | D47: =$B$41*$B$44 | E47: =$B$42 | F47: =MIN(B47,D47,E47) | G47: =IF(B47>E47, "SHIPMENT NEEDED!", "OK")
A48: FN2 | B48: 0 | C48: N | D48: =$B$41*$B$44 | E48: =$B$42 | F48: =MIN(B48,D48,E48) | G48: =IF(B48>E48, "SHIPMENT NEEDED!", "OK")
...

Sheet RESOURCE_MGR
A1: RESOURCE MANAGER - Zone-by-Zone Asset Allocation
A3: SECTION A: MACHINE ASSIGNMENTS BY ZONE
A5: Zone | B5: Section | C5: Machines Assigned | D5: Workers Needed | E5: Status
A6: Center | B6: Section 1 | C6: 20 | D6: =C6*5 | E6: OK
A7: Center | B7: Section 2 | C7: 20 | D7: =C7*5 | E7: OK
A8: Center | B8: Section 3 | C8: 17 | D8: =C8*5 | E8: OK
A9: West | B9: Section 1 | C9: 0 | D9: =C9*5 | E9: OK
A10: West | B10: Section 2 | C10: 0 | D10: =C10*5 | E10: OK
A11: West | B11: Section 3 | C11: 0 | D11: =C11*5 | E11: OK
A12: North | B12: Section 1 | C12: 0 | D12: =C12*5 | E12: OK
A13: North | B13: Section 2 | C13: 0 | D13: =C13*5 | E13: OK
A14: North | B14: Section 3 | C14: 0 | D14: =C14*5 | E14: OK
A15: East | B15: Section 1 | C15: 0 | D15: =C15*5 | E15: OK
A16: East | B16: Section 2 | C16: 0 | D16: =C16*5 | E16: OK
A17: East | B17: Section 3 | C17: 0 | D17: =C17*5 | E17: OK
... A20: South | B20: Section 3 | C20: 0 | D20: =C20*5 | E20: OK
A24: SECTION B: EXPANSION RECOMMENDATIONS BY ZONE
A26: Zone | B26: Target Capacity | C26: Current Machines | D26: Capacity Gap | E26: Recommendation
A27: Center | B27: =ZONE_CALCULATORS!B19 | C27: 156 | D27: =B27-(C27*200) | E27: =IF(D27>0, "Buy "&ROUNDUP(D27/200,0)&" machines", "OK")
A28: West | B28: =ZONE_CALCULATORS!B37 | C28: 0 | D28: =B28-(C28*200) | E28: =IF(D28>0, "Buy "&ROUNDUP(D28/200,0)&" machines", "OK")
A29: North | B29: =ZONE_CALCULATORS!B55 | C29: 0 | D29: =B29-(C29*200) | E29: =IF(D29>0, "Buy "&ROUNDUP(D29/200,0)&" machines", "OK")
A30: East | B30: =ZONE_CALCULATORS!B73 | C30: 0 | D30: =B30-(C30*200) | E30: =IF(D30>0, "Buy "&ROUNDUP(D30/200,0)&" machines", "OK")
A31: South | B31: =ZONE_CALCULATORS!B91 | C31: 0 | D31: =B31-(C31*200) | E31: =IF(D31>0, "Buy "&ROUNDUP(D31/200,0)&" machines", "OK")
A35: SECTION C: REAL ESTATE (MODULES) BY ZONE
A37: Zone | B37: Machines | C37: Module Slots | D37: Free Slots | E37: Recommendation
A38: Center | B38: 156 | C38: 0 | D38: =C38-B38 | E38: =IF(D38<5, "Buy module in Center", "OK")
A39: West | B39: 0 | C39: 0 | D39: =C39-B39 | E39: =IF(D39<5, "Buy module in West", "OK")
A40: North | B40: 0 | C40: 0 | D40: =C40-B40 | E40: =IF(D40<5, "Buy module in North", "OK")
A41: East | B41: 0 | C41: 0 | D41: =C41-B41 | E41: =IF(D41<5, "Buy module in East", "OK")
A42: South | B42: 0 | C42: 0 | D42: =C42-B42 | E42: =IF(D42<5, "Buy module in South", "OK")

Sheet UPLOAD_READY_PRODUCTION
A1: PRODUCTION DECISIONS - ExSim Upload (Zone-Mapped)
A2: Values linked from Zone Calculators
A4: Production Targets
A5: Zone | B5: Product | C5: Target | D5: Overtime
A6: Center | B6: A | C6: =ZONE_CALCULATORS!F19 | D6: =ZONE_CALCULATORS!C11
A7: West | B7: A | C7: =ZONE_CALCULATORS!F37 | D7: =ZONE_CALCULATORS!C29
A8: North | B8: A | C8: =ZONE_CALCULATORS!F55 | D8: =ZONE_CALCULATORS!C47
A9: East | B9: A | C9: =ZONE_CALCULATORS!F73 | D9: =ZONE_CALCULATORS!C65
A10: South | B10: A | C10: =ZONE_CALCULATORS!F91 | D10: =ZONE_CALCULATORS!C83
A13: Machine Purchases
A14: Zone | B14: Machine Type | C14: Quantity
A15: Center | B15: M1 | C15: 0
A16: Center | B16: M2 | C16: 0
A17: West | B17: M1 | C17: 0
A18: West | B18: M2 | C18: 0
A19: North | B19: M1 | C19: 0
A20: North | B20: M2 | C20: 0
A21: East | B21: M1 | C21: 0
A22: East | B22: M2 | C22: 0
A23: South | B23: M1 | C23: 0
A24: South | B24: M2 | C24: 0
A27: Section Assignments
A28: Zone | B28: Section | C28: Machines | D28: Workers
A29: Center | B29: Section 1 | C29: =RESOURCE_MGR!C6 | D29: =RESOURCE_MGR!D6
A30: Center | B30: Section 2 | C30: =RESOURCE_MGR!C7 | D30: =RESOURCE_MGR!D7
A31: Center | B31: Section 3 | C31: =RESOURCE_MGR!C8 | D31: =RESOURCE_MGR!D8
A32: West | B32: Section 1 | C32: =RESOURCE_MGR!C9 | D32: =RESOURCE_MGR!D9
A33: West | B33: Section 2 | C33: =RESOURCE_MGR!C10 | D33: =RESOURCE_MGR!D10
A34: West | B34: Section 3 | C34: =RESOURCE_MGR!C11 | D34: =RESOURCE_MGR!D11
A35: North | B35: Section 1 | C35: =RESOURCE_MGR!C12 | D35: =RESOURCE_MGR!D12
A36: North | B36: Section 2 | C36: =RESOURCE_MGR!C13 | D36: =RESOURCE_MGR!D13
A37: North | B37: Section 3 | C37: =RESOURCE_MGR!C14 | D37: =RESOURCE_MGR!D14
A38: East | B38: Section 1 | C38: =RESOURCE_MGR!C15 | D38: =RESOURCE_MGR!D15
A39: East | B39: Section 2 | C39: =RESOURCE_MGR!C16 | D39: =RESOURCE_MGR!D16
A40: East | B40: Section 3 | C40: =RESOURCE_MGR!C17 | D40: =RESOURCE_MGR!D17
... A43: South | B43: Section 3 | C43: =RESOURCE_MGR!C20 | D43: =RESOURCE_MGR!D20
